<?xml version="1.0" encoding="utf-8"?>
<!-- =================================================================================== -->
<!-- |    This document was autogenerated by xacro from bb.xacro                       | -->
<!-- |    EDITING THIS FILE BY HAND IS NOT RECOMMENDED                                 | -->
<!-- =================================================================================== -->
<robot name="bb8">
  <material name="blue">
    <color rgba="0 0 .8 1"/>
  </material>
  <material name="black">
    <color rgba="0 0 0 1"/>
  </material>
  <material name="white">
    <color rgba="1 1 1 1"/>
  </material>
  <material name="orange">
    <color rgba="1 .5 0 1"/>
  </material>
  <material name="grey">
    <color rgba=".5 .5 .5 1"/>
  </material>
  <material name="red">
    <color rgba="1 0 0 1"/>
  </material>
  <!-- links without visual -->
  <link name="bb9"/>
  <link name="bb9/roll"/>
  <link name="bb9/neck"/>
  <link name="bb9/torso"/>
  <joint name="roll" type="revolute">
    <mimic joint="neck" multiplier="0.5"/>
    <axis xyz="-1 0 0"/>
    <limit effort="10" lower="-0.523598775598" upper="0.523598775598" velocity="2"/>
    <child link="bb9/roll"/>
    <parent link="bb9"/>
  </joint>
  <joint name="wheel" type="continuous">
    <parent link="bb9/roll"/>
    <child link="bb9/wheel"/>
    <axis xyz="0 1 0"/>
    <origin xyz="0 0 0.27"/>
  </joint>
  <joint name="torso" type="revolute">
    <axis xyz="0 1 0"/>
    <limit effort="10" lower="-0.785398163397" upper="0.785398163397" velocity="2"/>
    <child link="bb9/torso"/>
    <parent link="bb9/roll"/>
    <origin xyz="0 0 0.27"/>
  </joint>
  <joint name="neck" type="revolute">
    <parent link="bb9/torso"/>
    <child link="bb9/neck"/>
    <origin xyz="0 0 0.27"/>
    <axis xyz="-1 0 0"/>
    <limit effort="10" lower="-0.523598775598" upper="0.523598775598" velocity="2"/>
  </joint>
  <joint name="head" type="fixed">
    <parent link="bb9/neck"/>
    <child link="bb9/head"/>
    <origin xyz="0 0 0.027"/>
  </joint>
  <link name="bb9/head">
    <visual>
      <geometry>
        <cylinder length="0.0864" radius="0.135"/>
      </geometry>
      <material name="black"/>
    </visual>
  </link>
  <link name="bb9/eye">
    <visual>
      <geometry>
        <cylinder length="0.0945" radius="0.027"/>
      </geometry>
      <material name="red"/>
    </visual>
  </link>
  <joint name="eye" type="fixed">
    <parent link="bb9/head"/>
    <child link="bb9/eye"/>
    <origin rpy="0 1.57079632679 0" xyz="0.0891 0 0"/>
  </joint>
  <link name="bb9/crown">
    <visual>
      <geometry>
        <cylinder length="0.054" radius="0.0945"/>
      </geometry>
      <material name="grey"/>
    </visual>
  </link>
  <joint name="crown" type="fixed">
    <parent link="bb9/head"/>
    <child link="bb9/crown"/>
    <origin xyz="0 0 0.0297"/>
  </joint>
  <!-- wheel links -->
  <link name="bb9/wheel">
    <visual>
      <geometry>
        <sphere radius="0.27"/>
      </geometry>
      <material name="black"/>
    </visual>
  </link>
  <link name="bb9/cx">
    <visual>
      <geometry>
        <cylinder length="0.4779" radius="0.135"/>
      </geometry>
      <material name="grey"/>
    </visual>
  </link>
  <joint name="cx" type="fixed">
    <parent link="bb9/wheel"/>
    <child link="bb9/cx"/>
    <origin rpy="1.57079632679 0 0"/>
  </joint>
  <link name="bb9/cz">
    <visual>
      <geometry>
        <cylinder length="0.4779" radius="0.135"/>
      </geometry>
      <material name="grey"/>
    </visual>
  </link>
  <joint name="cz" type="fixed">
    <parent link="bb9/wheel"/>
    <child link="bb9/cz"/>
    <origin rpy="0 0 0"/>
  </joint>
  <link name="bb9/cy">
    <visual>
      <geometry>
        <cylinder length="0.4779" radius="0.135"/>
      </geometry>
      <material name="grey"/>
    </visual>
  </link>
  <joint name="cy" type="fixed">
    <parent link="bb9/wheel"/>
    <child link="bb9/cy"/>
    <origin rpy="0 1.57079632679 0"/>
  </joint>
</robot>

