<?xml version="1.0" encoding="utf-8"?>
<!-- =================================================================================== -->
<!-- |    This document was autogenerated by xacro from d.xacro                        | -->
<!-- |    EDITING THIS FILE BY HAND IS NOT RECOMMENDED                                 | -->
<!-- =================================================================================== -->
<robot name="d0">
  <material name="blue">
    <color rgba="0 0 .8 1"/>
  </material>
  <material name="black">
    <color rgba="0 0 0 1"/>
  </material>
  <material name="white">
    <color rgba="1 1 1 1"/>
  </material>
  <material name="orange">
    <color rgba="1 .5 0 1"/>
  </material>
  <material name="grey">
    <color rgba=".5 .5 .5 1"/>
  </material>
  <material name="red">
    <color rgba="1 0 0 1"/>
  </material>
  <material name="green">
    <color rgba="0 0.6 0 1"/>
  </material>
  <!-- links without visual -->
  <link name="d9"/>
  <link name="d9/roll"/>
  <link name="d9/neck"/>
  <link name="d9/torso"/>
  <joint name="roll" type="revolute">
    <mimic joint="neck" multiplier="0.5"/>
    <axis xyz="-1 0 0"/>
    <limit effort="10" lower="-0.523598775598" upper="0.523598775598" velocity="2"/>
    <child link="d9/roll"/>
    <parent link="d9"/>
  </joint>
  <joint name="wheel" type="continuous">
    <parent link="d9/roll"/>
    <child link="d9/wheel"/>
    <axis xyz="0 1 0"/>
    <origin xyz="0 0 0.16"/>
  </joint>
  <joint name="torso" type="revolute">
    <axis xyz="0 1 0"/>
    <limit effort="10" lower="-0.785398163397" upper="0.785398163397" velocity="2"/>
    <child link="d9/torso"/>
    <parent link="d9/roll"/>
    <origin xyz="0 0 0.16"/>
  </joint>
  <joint name="neck" type="revolute">
    <parent link="d9/torso"/>
    <child link="d9/neck"/>
    <origin xyz="0 0 0.192"/>
    <axis xyz="-1 0 0"/>
    <limit effort="10" lower="-0.523598775598" upper="0.523598775598" velocity="2"/>
  </joint>
  <joint name="head" type="fixed">
    <parent link="d9/neck"/>
    <child link="d9/head"/>
    <origin xyz="0 0 0.072"/>
  </joint>
  <!-- wheel links -->
  <link name="d9/wheel">
    <visual>
      <origin rpy="1.57079632679 0 0"/>
      <geometry>
        <cylinder length="0.096" radius="0.16"/>
      </geometry>
      <material name="black"/>
    </visual>
  </link>
  <link name="d9/wheel1">
    <visual>
      <origin rpy="0 0 0" xyz="0.064 0 0.064"/>
      <geometry>
        <box size="0.064 0.09696 0.064"/>
      </geometry>
      <material name="red"/>
    </visual>
    <visual>
      <origin rpy="0 0 0" xyz="-0.064 0 0.064"/>
      <geometry>
        <box size="0.064 0.09696 0.064"/>
      </geometry>
      <material name="red"/>
    </visual>
  </link>
  <joint name="wheel1" type="fixed">
    <parent link="d9/wheel"/>
    <child link="d9/wheel1"/>
  </joint>
  <!-- torso links -->
  <link name="d9/torso1">
    <visual>
      <origin xyz="0 0.04992 0.096"/>
      <geometry>
        <cylinder length="0.192" radius="0.0128"/>
      </geometry>
      <material name="grey"/>
    </visual>
  </link>
  <joint name="torso1" type="fixed">
    <parent link="d9/torso"/>
    <child link="d9/torso1"/>
  </joint>
  <link name="d9/torso2">
    <visual>
      <origin xyz="0 0 0.192"/>
      <geometry>
        <box size="0.0608 0.0912 0.032"/>
      </geometry>
      <material name="black"/>
    </visual>
  </link>
  <joint name="torso2" type="fixed">
    <parent link="d9/torso"/>
    <child link="d9/torso2"/>
  </joint>
  <link name="d9/torso3">
    <visual>
      <origin xyz="0 0 0.216"/>
      <geometry>
        <box size="0.048 0.0672 0.048"/>
      </geometry>
      <material name="grey"/>
    </visual>
  </link>
  <joint name="torso3" type="fixed">
    <parent link="d9/torso"/>
    <child link="d9/torso3"/>
  </joint>
  <!-- head links -->
  <link name="d9/head">
    <visual>
      <origin rpy="0 1.57079632679 0" xyz="-0.08 0 0"/>
      <geometry>
        <cylinder length="0.008" radius="0.064"/>
      </geometry>
      <material name="black"/>
    </visual>
    <visual>
      <origin rpy="0 1.57079632679 0" xyz="-0.072 0 0"/>
      <geometry>
        <cylinder length="0.008" radius="0.0624"/>
      </geometry>
      <material name="black"/>
    </visual>
    <visual>
      <origin rpy="0 1.57079632679 0" xyz="-0.064 0 0"/>
      <geometry>
        <cylinder length="0.008" radius="0.0608"/>
      </geometry>
      <material name="black"/>
    </visual>
    <visual>
      <origin rpy="0 1.57079632679 0" xyz="-0.056 0 0"/>
      <geometry>
        <cylinder length="0.008" radius="0.0592"/>
      </geometry>
      <material name="black"/>
    </visual>
    <visual>
      <origin rpy="0 1.57079632679 0" xyz="-0.048 0 0"/>
      <geometry>
        <cylinder length="0.008" radius="0.0576"/>
      </geometry>
      <material name="black"/>
    </visual>
    <visual>
      <origin rpy="0 1.57079632679 0" xyz="-0.04 0 0"/>
      <geometry>
        <cylinder length="0.008" radius="0.056"/>
      </geometry>
      <material name="black"/>
    </visual>
    <visual>
      <origin rpy="0 1.57079632679 0" xyz="-0.032 0 0"/>
      <geometry>
        <cylinder length="0.008" radius="0.0544"/>
      </geometry>
      <material name="black"/>
    </visual>
    <visual>
      <origin rpy="0 1.57079632679 0" xyz="-0.024 0 0"/>
      <geometry>
        <cylinder length="0.008" radius="0.0528"/>
      </geometry>
      <material name="black"/>
    </visual>
    <visual>
      <origin rpy="0 1.57079632679 0" xyz="-0.016 0 0"/>
      <geometry>
        <cylinder length="0.008" radius="0.0512"/>
      </geometry>
      <material name="black"/>
    </visual>
    <visual>
      <origin rpy="0 1.57079632679 0" xyz="-0.008 0 0"/>
      <geometry>
        <cylinder length="0.008" radius="0.0496"/>
      </geometry>
      <material name="black"/>
    </visual>
    <visual>
      <origin rpy="0 1.57079632679 0" xyz="0.0 0 0"/>
      <geometry>
        <cylinder length="0.008" radius="0.048"/>
      </geometry>
      <material name="black"/>
    </visual>
    <visual>
      <origin rpy="0 1.57079632679 0" xyz="0.008 0 0"/>
      <geometry>
        <cylinder length="0.008" radius="0.0464"/>
      </geometry>
      <material name="black"/>
    </visual>
    <visual>
      <origin rpy="0 1.57079632679 0" xyz="0.016 0 0"/>
      <geometry>
        <cylinder length="0.008" radius="0.0448"/>
      </geometry>
      <material name="black"/>
    </visual>
    <visual>
      <origin rpy="0 1.57079632679 0" xyz="0.024 0 0"/>
      <geometry>
        <cylinder length="0.008" radius="0.0432"/>
      </geometry>
      <material name="black"/>
    </visual>
    <visual>
      <origin rpy="0 1.57079632679 0" xyz="0.032 0 0"/>
      <geometry>
        <cylinder length="0.008" radius="0.0416"/>
      </geometry>
      <material name="black"/>
    </visual>
    <visual>
      <origin rpy="0 1.57079632679 0" xyz="0.04 0 0"/>
      <geometry>
        <cylinder length="0.008" radius="0.04"/>
      </geometry>
      <material name="black"/>
    </visual>
    <visual>
      <origin rpy="0 1.57079632679 0" xyz="0.048 0 0"/>
      <geometry>
        <cylinder length="0.008" radius="0.0384"/>
      </geometry>
      <material name="black"/>
    </visual>
    <visual>
      <origin rpy="0 1.57079632679 0" xyz="0.056 0 0"/>
      <geometry>
        <cylinder length="0.008" radius="0.0368"/>
      </geometry>
      <material name="black"/>
    </visual>
    <visual>
      <origin rpy="0 1.57079632679 0" xyz="0.064 0 0"/>
      <geometry>
        <cylinder length="0.008" radius="0.0352"/>
      </geometry>
      <material name="black"/>
    </visual>
  </link>
  <link name="d9/head2">
    <visual>
      <origin rpy="0 1.57079632679 0" xyz="0.064 0 0"/>
      <geometry>
        <cylinder length="0.008" radius="0.0352"/>
      </geometry>
      <material name="red"/>
    </visual>
    <visual>
      <origin rpy="0 1.57079632679 0" xyz="0.072 0 0"/>
      <geometry>
        <cylinder length="0.008" radius="0.0336"/>
      </geometry>
      <material name="red"/>
    </visual>
    <visual>
      <origin rpy="0 1.57079632679 0" xyz="0.08 0 0"/>
      <geometry>
        <cylinder length="0.008" radius="0.032"/>
      </geometry>
      <material name="red"/>
    </visual>
    <visual>
      <origin rpy="0 1.57079632679 0" xyz="0.088 0 0"/>
      <geometry>
        <cylinder length="0.008" radius="0.0304"/>
      </geometry>
      <material name="red"/>
    </visual>
    <visual>
      <origin rpy="0 1.57079632679 0" xyz="0.096 0 0"/>
      <geometry>
        <cylinder length="0.008" radius="0.0288"/>
      </geometry>
      <material name="red"/>
    </visual>
    <visual>
      <origin rpy="0 1.57079632679 0" xyz="0.104 0 0"/>
      <geometry>
        <cylinder length="0.008" radius="0.0272"/>
      </geometry>
      <material name="red"/>
    </visual>
  </link>
  <joint name="head2" type="fixed">
    <parent link="d9/head"/>
    <child link="d9/head2"/>
  </joint>
  <link name="d9/antenna">
    <visual>
      <origin rpy="0 1.25663706144 0" xyz="-0.112 0 -0.064"/>
      <geometry>
        <cylinder length="0.16" radius="0.0016"/>
      </geometry>
      <material name="black"/>
    </visual>
    <visual>
      <origin rpy="0.314159265359 1.88495559215 0" xyz="-0.112 0.048 0.048"/>
      <geometry>
        <cylinder length="0.16" radius="0.0016"/>
      </geometry>
      <material name="black"/>
    </visual>
    <visual>
      <origin rpy="-0.314159265359 1.88495559215 0" xyz="-0.112 -0.048 0.048"/>
      <geometry>
        <cylinder length="0.16" radius="0.0016"/>
      </geometry>
      <material name="black"/>
    </visual>
  </link>
  <joint name="antenna" type="fixed">
    <parent link="d9/head"/>
    <child link="d9/antenna"/>
  </joint>
  <link name="d9/eyes">
    <visual>
      <origin rpy="0 1.72787595947 -0.1308996939" xyz="0 0.032 0.032"/>
      <geometry>
        <cylinder length="0.08" radius="0.0056"/>
      </geometry>
      <material name="grey"/>
    </visual>
    <visual>
      <origin rpy="0 1.72787595947 0.1308996939" xyz="0 -0.032 0.032"/>
      <geometry>
        <cylinder length="0.08" radius="0.0056"/>
      </geometry>
      <material name="grey"/>
    </visual>
    <visual>
      <origin rpy="0 1.76714586764 0" xyz="0 0 0.0448"/>
      <geometry>
        <cylinder length="0.08" radius="0.0056"/>
      </geometry>
      <material name="grey"/>
    </visual>
  </link>
  <joint name="eyes" type="fixed">
    <parent link="d9/head"/>
    <child link="d9/eyes"/>
  </joint>
</robot>

